Workbook

Sheet 使い方
A1: 棚卸し・発注表（試作）
A3: 【社員さんの作業】
A4: 1. スマホで「棚卸し入力」シートを開く
A5: 2. 上から順にキッチンを回り、黄色の「在庫」欄に数を入れるだけ
A6: 3. 「発注数」は自動で計算されます（定数 − 在庫）。発注が必要な行はオレンジ色になります
A7: 4. 「発注リスト」シートに、発注が必要な物だけが自動でまとまります → そのまま発注・印刷
A9: 【品目の追加・修正（管理者）】
A10: ・並び順は「キッチンを回る順番」にしてください（場所ごとにまとめる）
A11: ・定数＝「次の発注までにこれだけあれば足りる量」。料理長・社員さんに決めてもらう
A12: ・行を追加したら、発注数・連番の列の式も下にコピーしてください
A14: ※ 品目・数量はすべて架空のサンプルです

Sheet 棚卸し入力
A1: 場所 | B1: 品名 | C1: 単位 | D1: 業者 | E1: 定数 | F1: 在庫 | G1: 発注数 | H1: 備考 | I1: 0
A2: 冷蔵庫①上段 | B2: 鶏もも肉 | C2: kg | D2: A精肉 | E2: 10 | F2: 4 | G2: =IF(F2="","",MAX(0,E2-F2)) -> 6 | I2: =IF(N(G2)>0,MAX(I$1:I1)+1,"") -> 1
A3: 冷蔵庫①上段 | B3: 豚バラ肉 | C3: kg | D3: A精肉 | E3: 6 | F3: 5 | G3: =IF(F3="","",MAX(0,E3-F3)) -> 1 | I3: =IF(N(G3)>0,MAX(I$1:I2)+1,"") -> 2
A4: 冷蔵庫①下段 | B4: 卵 | C4: パック | D4: B青果 | E4: 8 | F4: 3 | G4: =IF(F4="","",MAX(0,E4-F4)) -> 5 | I4: =IF(N(G4)>0,MAX(I$1:I3)+1,"") -> 3
A5: 冷蔵庫①下段 | B5: キャベツ | C5: 玉 | D5: B青果 | E5: 6 | F5: 6 | G5: =IF(F5="","",MAX(0,E5-F5)) -> 0 | I5: =IF(N(G5)>0,MAX(I$1:I4)+1,"")
A6: 冷蔵庫①下段 | B6: 玉ねぎ | C6: 箱 | D6: B青果 | E6: 2 | F6: 1 | G6: =IF(F6="","",MAX(0,E6-F6)) -> 1 | I6: =IF(N(G6)>0,MAX(I$1:I5)+1,"") -> 4
A7: 冷凍庫 | B7: 冷凍エビ | C7: 袋 | D7: C食品 | E7: 5 | F7: 2 | G7: =IF(F7="","",MAX(0,E7-F7)) -> 3 | I7: =IF(N(G7)>0,MAX(I$1:I6)+1,"") -> 5
A8: 冷凍庫 | B8: フライドポテト | C8: 袋 | D8: C食品 | E8: 8 | F8: 7 | G8: =IF(F8="","",MAX(0,E8-F8)) -> 1 | I8: =IF(N(G8)>0,MAX(I$1:I7)+1,"") -> 6
A9: 冷凍庫 | B9: 唐揚げ粉 | C9: 袋 | D9: C食品 | E9: 4 | F9: 4 | G9: =IF(F9="","",MAX(0,E9-F9)) -> 0 | I9: =IF(N(G9)>0,MAX(I$1:I8)+1,"")
A10: 乾物棚 | B10: 米 | C10: 袋(10kg) | D10: D米店 | E10: 6 | F10: 2 | G10: =IF(F10="","",MAX(0,E10-F10)) -> 4 | I10: =IF(N(G10)>0,MAX(I$1:I9)+1,"") -> 7
A11: 乾物棚 | B11: パスタ | C11: 袋 | D11: C食品 | E11: 10 | F11: 9 | G11: =IF(F11="","",MAX(0,E11-F11)) -> 1 | I11: =IF(N(G11)>0,MAX(I$1:I10)+1,"") -> 8
A12: 乾物棚 | B12: 薄力粉 | C12: 袋 | D12: C食品 | E12: 3 | F12: 1 | G12: =IF(F12="","",MAX(0,E12-F12)) -> 2 | I12: =IF(N(G12)>0,MAX(I$1:I11)+1,"") -> 9
A13: 調味料棚 | B13: 醤油 | C13: 本 | D13: C食品 | E13: 4 | F13: 2 | G13: =IF(F13="","",MAX(0,E13-F13)) -> 2 | I13: =IF(N(G13)>0,MAX(I$1:I12)+1,"") -> 10
... A17: 消耗品棚 | B17: ゴム手袋 | C17: 箱 | D17: E資材 | E17: 4 | F17: 4 | G17: =IF(F17="","",MAX(0,E17-F17)) -> 0 | I17: =IF(N(G17)>0,MAX(I$1:I16)+1,"")
A18: 消耗品棚 | B18: 洗剤 | C18: 本 | D18: E資材 | E18: 3 | G18: =IF(F18="","",MAX(0,E18-F18)) | I18: =IF(N(G18)>0,MAX(I$1:I17)+1,"")

Sheet 発注リスト
A1: No | B1: 業者 | C1: 品名 | D1: 発注数 | E1: 単位 | F1: 場所
A2: =IF(C2="","",1) -> 1 | B2: =IFERROR(INDEX(棚卸し入力!$D:$D,MATCH(1,棚卸し入力!$I:$I,0)),"") -> A精肉 | C2: =IFERROR(INDEX(棚卸し入力!$B:$B,MATCH(1,棚卸し入力!$I:$I,0)),"") -> 鶏もも肉 | D2: =IFERROR(INDEX(棚卸し入力!$G:$G,MATCH(1,棚卸し入力!$I:$I,0)),"") -> 6 | E2: =IFERROR(INDEX(棚卸し入力!$C:$C,MATCH(1,棚卸し入力!$I:$I,0)),"") -> kg | F2: =IFERROR(INDEX(棚卸し入力!$A:$A,MATCH(1,棚卸し入力!$I:$I,0)),"") -> 冷蔵庫①上段
A3: =IF(C3="","",2) -> 2 | B3: =IFERROR(INDEX(棚卸し入力!$D:$D,MATCH(2,棚卸し入力!$I:$I,0)),"") -> A精肉 | C3: =IFERROR(INDEX(棚卸し入力!$B:$B,MATCH(2,棚卸し入力!$I:$I,0)),"") -> 豚バラ肉 | D3: =IFERROR(INDEX(棚卸し入力!$G:$G,MATCH(2,棚卸し入力!$I:$I,0)),"") -> 1 | E3: =IFERROR(INDEX(棚卸し入力!$C:$C,MATCH(2,棚卸し入力!$I:$I,0)),"") -> kg | F3: =IFERROR(INDEX(棚卸し入力!$A:$A,MATCH(2,棚卸し入力!$I:$I,0)),"") -> 冷蔵庫①上段
A4: =IF(C4="","",3) -> 3 | B4: =IFERROR(INDEX(棚卸し入力!$D:$D,MATCH(3,棚卸し入力!$I:$I,0)),"") -> B青果 | C4: =IFERROR(INDEX(棚卸し入力!$B:$B,MATCH(3,棚卸し入力!$I:$I,0)),"") -> 卵 | D4: =IFERROR(INDEX(棚卸し入力!$G:$G,MATCH(3,棚卸し入力!$I:$I,0)),"") -> 5 | E4: =IFERROR(INDEX(棚卸し入力!$C:$C,MATCH(3,棚卸し入力!$I:$I,0)),"") -> パック | F4: =IFERROR(INDEX(棚卸し入力!$A:$A,MATCH(3,棚卸し入力!$I:$I,0)),"") -> 冷蔵庫①下段
A5: =IF(C5="","",4) -> 4 | B5: =IFERROR(INDEX(棚卸し入力!$D:$D,MATCH(4,棚卸し入力!$I:$I,0)),"") -> B青果 | C5: =IFERROR(INDEX(棚卸し入力!$B:$B,MATCH(4,棚卸し入力!$I:$I,0)),"") -> 玉ねぎ | D5: =IFERROR(INDEX(棚卸し入力!$G:$G,MATCH(4,棚卸し入力!$I:$I,0)),"") -> 1 | E5: =IFERROR(INDEX(棚卸し入力!$C:$C,MATCH(4,棚卸し入力!$I:$I,0)),"") -> 箱 | F5: =IFERROR(INDEX(棚卸し入力!$A:$A,MATCH(4,棚卸し入力!$I:$I,0)),"") -> 冷蔵庫①下段
A6: =IF(C6="","",5) -> 5 | B6: =IFERROR(INDEX(棚卸し入力!$D:$D,MATCH(5,棚卸し入力!$I:$I,0)),"") -> C食品 | C6: =IFERROR(INDEX(棚卸し入力!$B:$B,MATCH(5,棚卸し入力!$I:$I,0)),"") -> 冷凍エビ | D6: =IFERROR(INDEX(棚卸し入力!$G:$G,MATCH(5,棚卸し入力!$I:$I,0)),"") -> 3 | E6: =IFERROR(INDEX(棚卸し入力!$C:$C,MATCH(5,棚卸し入力!$I:$I,0)),"") -> 袋 | F6: =IFERROR(INDEX(棚卸し入力!$A:$A,MATCH(5,棚卸し入力!$I:$I,0)),"") -> 冷凍庫
A7: =IF(C7="","",6) -> 6 | B7: =IFERROR(INDEX(棚卸し入力!$D:$D,MATCH(6,棚卸し入力!$I:$I,0)),"") -> C食品 | C7: =IFERROR(INDEX(棚卸し入力!$B:$B,MATCH(6,棚卸し入力!$I:$I,0)),"") -> フライドポテト | D7: =IFERROR(INDEX(棚卸し入力!$G:$G,MATCH(6,棚卸し入力!$I:$I,0)),"") -> 1 | E7: =IFERROR(INDEX(棚卸し入力!$C:$C,MATCH(6,棚卸し入力!$I:$I,0)),"") -> 袋 | F7: =IFERROR(INDEX(棚卸し入力!$A:$A,MATCH(6,棚卸し入力!$I:$I,0)),"") -> 冷凍庫
A8: =IF(C8="","",7) -> 7 | B8: =IFERROR(INDEX(棚卸し入力!$D:$D,MATCH(7,棚卸し入力!$I:$I,0)),"") -> D米店 | C8: =IFERROR(INDEX(棚卸し入力!$B:$B,MATCH(7,棚卸し入力!$I:$I,0)),"") -> 米 | D8: =IFERROR(INDEX(棚卸し入力!$G:$G,MATCH(7,棚卸し入力!$I:$I,0)),"") -> 4 | E8: =IFERROR(INDEX(棚卸し入力!$C:$C,MATCH(7,棚卸し入力!$I:$I,0)),"") -> 袋(10kg) | F8: =IFERROR(INDEX(棚卸し入力!$A:$A,MATCH(7,棚卸し入力!$I:$I,0)),"") -> 乾物棚
A9: =IF(C9="","",8) -> 8 | B9: =IFERROR(INDEX(棚卸し入力!$D:$D,MATCH(8,棚卸し入力!$I:$I,0)),"") -> C食品 | C9: =IFERROR(INDEX(棚卸し入力!$B:$B,MATCH(8,棚卸し入力!$I:$I,0)),"") -> パスタ | D9: =IFERROR(INDEX(棚卸し入力!$G:$G,MATCH(8,棚卸し入力!$I:$I,0)),"") -> 1 | E9: =IFERROR(INDEX(棚卸し入力!$C:$C,MATCH(8,棚卸し入力!$I:$I,0)),"") -> 袋 | F9: =IFERROR(INDEX(棚卸し入力!$A:$A,MATCH(8,棚卸し入力!$I:$I,0)),"") -> 乾物棚
A10: =IF(C10="","",9) -> 9 | B10: =IFERROR(INDEX(棚卸し入力!$D:$D,MATCH(9,棚卸し入力!$I:$I,0)),"") -> C食品 | C10: =IFERROR(INDEX(棚卸し入力!$B:$B,MATCH(9,棚卸し入力!$I:$I,0)),"") -> 薄力粉 | D10: =IFERROR(INDEX(棚卸し入力!$G:$G,MATCH(9,棚卸し入力!$I:$I,0)),"") -> 2 | E10: =IFERROR(INDEX(棚卸し入力!$C:$C,MATCH(9,棚卸し入力!$I:$I,0)),"") -> 袋 | F10: =IFERROR(INDEX(棚卸し入力!$A:$A,MATCH(9,棚卸し入力!$I:$I,0)),"") -> 乾物棚
A11: =IF(C11="","",10) -> 10 | B11: =IFERROR(INDEX(棚卸し入力!$D:$D,MATCH(10,棚卸し入力!$I:$I,0)),"") -> C食品 | C11: =IFERROR(INDEX(棚卸し入力!$B:$B,MATCH(10,棚卸し入力!$I:$I,0)),"") -> 醤油 | D11: =IFERROR(INDEX(棚卸し入力!$G:$G,MATCH(10,棚卸し入力!$I:$I,0)),"") -> 2 | E11: =IFERROR(INDEX(棚卸し入力!$C:$C,MATCH(10,棚卸し入力!$I:$I,0)),"") -> 本 | F11: =IFERROR(INDEX(棚卸し入力!$A:$A,MATCH(10,棚卸し入力!$I:$I,0)),"") -> 調味料棚
A12: =IF(C12="","",11) -> 11 | B12: =IFERROR(INDEX(棚卸し入力!$D:$D,MATCH(11,棚卸し入力!$I:$I,0)),"") -> C食品 | C12: =IFERROR(INDEX(棚卸し入力!$B:$B,MATCH(11,棚卸し入力!$I:$I,0)),"") -> サラダ油 | D12: =IFERROR(INDEX(棚卸し入力!$G:$G,MATCH(11,棚卸し入力!$I:$I,0)),"") -> 2 | E12: =IFERROR(INDEX(棚卸し入力!$C:$C,MATCH(11,棚卸し入力!$I:$I,0)),"") -> 缶 | F12: =IFERROR(INDEX(棚卸し入力!$A:$A,MATCH(11,棚卸し入力!$I:$I,0)),"") -> 調味料棚
A13: =IF(C13="","",12) -> 12 | B13: =IFERROR(INDEX(棚卸し入力!$D:$D,MATCH(12,棚卸し入力!$I:$I,0)),"") -> E資材 | C13: =IFERROR(INDEX(棚卸し入力!$B:$B,MATCH(12,棚卸し入力!$I:$I,0)),"") -> ラップ | D13: =IFERROR(INDEX(棚卸し入力!$G:$G,MATCH(12,棚卸し入力!$I:$I,0)),"") -> 3 | E13: =IFERROR(INDEX(棚卸し入力!$C:$C,MATCH(12,棚卸し入力!$I:$I,0)),"") -> 本 | F13: =IFERROR(INDEX(棚卸し入力!$A:$A,MATCH(12,棚卸し入力!$I:$I,0)),"") -> 消耗品棚
A14: =IF(C14="","",13) | B14: =IFERROR(INDEX(棚卸し入力!$D:$D,MATCH(13,棚卸し入力!$I:$I,0)),"") | C14: =IFERROR(INDEX(棚卸し入力!$B:$B,MATCH(13,棚卸し入力!$I:$I,0)),"") | D14: =IFERROR(INDEX(棚卸し入力!$G:$G,MATCH(13,棚卸し入力!$I:$I,0)),"") | E14: =IFERROR(INDEX(棚卸し入力!$C:$C,MATCH(13,棚卸し入力!$I:$I,0)),"") | F14: =IFERROR(INDEX(棚卸し入力!$A:$A,MATCH(13,棚卸し入力!$I:$I,0)),"")
A15: =IF(C15="","",14) | B15: =IFERROR(INDEX(棚卸し入力!$D:$D,MATCH(14,棚卸し入力!$I:$I,0)),"") | C15: =IFERROR(INDEX(棚卸し入力!$B:$B,MATCH(14,棚卸し入力!$I:$I,0)),"") | D15: =IFERROR(INDEX(棚卸し入力!$G:$G,MATCH(14,棚卸し入力!$I:$I,0)),"") | E15: =IFERROR(INDEX(棚卸し入力!$C:$C,MATCH(14,棚卸し入力!$I:$I,0)),"") | F15: =IFERROR(INDEX(棚卸し入力!$A:$A,MATCH(14,棚卸し入力!$I:$I,0)),"")
A16: =IF(C16="","",15) | B16: =IFERROR(INDEX(棚卸し入力!$D:$D,MATCH(15,棚卸し入力!$I:$I,0)),"") | C16: =IFERROR(INDEX(棚卸し入力!$B:$B,MATCH(15,棚卸し入力!$I:$I,0)),"") | D16: =IFERROR(INDEX(棚卸し入力!$G:$G,MATCH(15,棚卸し入力!$I:$I,0)),"") | E16: =IFERROR(INDEX(棚卸し入力!$C:$C,MATCH(15,棚卸し入力!$I:$I,0)),"") | F16: =IFERROR(INDEX(棚卸し入力!$A:$A,MATCH(15,棚卸し入力!$I:$I,0)),"")
A17: =IF(C17="","",16) | B17: =IFERROR(INDEX(棚卸し入力!$D:$D,MATCH(16,棚卸し入力!$I:$I,0)),"") | C17: =IFERROR(INDEX(棚卸し入力!$B:$B,MATCH(16,棚卸し入力!$I:$I,0)),"") | D17: =IFERROR(INDEX(棚卸し入力!$G:$G,MATCH(16,棚卸し入力!$I:$I,0)),"") | E17: =IFERROR(INDEX(棚卸し入力!$C:$C,MATCH(16,棚卸し入力!$I:$I,0)),"") | F17: =IFERROR(INDEX(棚卸し入力!$A:$A,MATCH(16,棚卸し入力!$I:$I,0)),"")
A18: =IF(C18="","",17) | B18: =IFERROR(INDEX(棚卸し入力!$D:$D,MATCH(17,棚卸し入力!$I:$I,0)),"") | C18: =IFERROR(INDEX(棚卸し入力!$B:$B,MATCH(17,棚卸し入力!$I:$I,0)),"") | D18: =IFERROR(INDEX(棚卸し入力!$G:$G,MATCH(17,棚卸し入力!$I:$I,0)),"") | E18: =IFERROR(INDEX(棚卸し入力!$C:$C,MATCH(17,棚卸し入力!$I:$I,0)),"") | F18: =IFERROR(INDEX(棚卸し入力!$A:$A,MATCH(17,棚卸し入力!$I:$I,0)),"")
A19: =IF(C19="","",18) | B19: =IFERROR(INDEX(棚卸し入力!$D:$D,MATCH(18,棚卸し入力!$I:$I,0)),"") | C19: =IFERROR(INDEX(棚卸し入力!$B:$B,MATCH(18,棚卸し入力!$I:$I,0)),"") | D19: =IFERROR(INDEX(棚卸し入力!$G:$G,MATCH(18,棚卸し入力!$I:$I,0)),"") | E19: =IFERROR(INDEX(棚卸し入力!$C:$C,MATCH(18,棚卸し入力!$I:$I,0)),"") | F19: =IFERROR(INDEX(棚卸し入力!$A:$A,MATCH(18,棚卸し入力!$I:$I,0)),"")
A20: =IF(C20="","",19) | B20: =IFERROR(INDEX(棚卸し入力!$D:$D,MATCH(19,棚卸し入力!$I:$I,0)),"") | C20: =IFERROR(INDEX(棚卸し入力!$B:$B,MATCH(19,棚卸し入力!$I:$I,0)),"") | D20: =IFERROR(INDEX(棚卸し入力!$G:$G,MATCH(19,棚卸し入力!$I:$I,0)),"") | E20: =IFERROR(INDEX(棚卸し入力!$C:$C,MATCH(19,棚卸し入力!$I:$I,0)),"") | F20: =IFERROR(INDEX(棚卸し入力!$A:$A,MATCH(19,棚卸し入力!$I:$I,0)),"")
A21: =IF(C21="","",20) | B21: =IFERROR(INDEX(棚卸し入力!$D:$D,MATCH(20,棚卸し入力!$I:$I,0)),"") | C21: =IFERROR(INDEX(棚卸し入力!$B:$B,MATCH(20,棚卸し入力!$I:$I,0)),"") | D21: =IFERROR(INDEX(棚卸し入力!$G:$G,MATCH(20,棚卸し入力!$I:$I,0)),"") | E21: =IFERROR(INDEX(棚卸し入力!$C:$C,MATCH(20,棚卸し入力!$I:$I,0)),"") | F21: =IFERROR(INDEX(棚卸し入力!$A:$A,MATCH(20,棚卸し入力!$I:$I,0)),"")
A22: =IF(C22="","",21) | B22: =IFERROR(INDEX(棚卸し入力!$D:$D,MATCH(21,棚卸し入力!$I:$I,0)),"") | C22: =IFERROR(INDEX(棚卸し入力!$B:$B,MATCH(21,棚卸し入力!$I:$I,0)),"") | D22: =IFERROR(INDEX(棚卸し入力!$G:$G,MATCH(21,棚卸し入力!$I:$I,0)),"") | E22: =IFERROR(INDEX(棚卸し入力!$C:$C,MATCH(21,棚卸し入力!$I:$I,0)),"") | F22: =IFERROR(INDEX(棚卸し入力!$A:$A,MATCH(21,棚卸し入力!$I:$I,0)),"")
A23: =IF(C23="","",22) | B23: =IFERROR(INDEX(棚卸し入力!$D:$D,MATCH(22,棚卸し入力!$I:$I,0)),"") | C23: =IFERROR(INDEX(棚卸し入力!$B:$B,MATCH(22,棚卸し入力!$I:$I,0)),"") | D23: =IFERROR(INDEX(棚卸し入力!$G:$G,MATCH(22,棚卸し入力!$I:$I,0)),"") | E23: =IFERROR(INDEX(棚卸し入力!$C:$C,MATCH(22,棚卸し入力!$I:$I,0)),"") | F23: =IFERROR(INDEX(棚卸し入力!$A:$A,MATCH(22,棚卸し入力!$I:$I,0)),"")
A24: =IF(C24="","",23) | B24: =IFERROR(INDEX(棚卸し入力!$D:$D,MATCH(23,棚卸し入力!$I:$I,0)),"") | C24: =IFERROR(INDEX(棚卸し入力!$B:$B,MATCH(23,棚卸し入力!$I:$I,0)),"") | D24: =IFERROR(INDEX(棚卸し入力!$G:$G,MATCH(23,棚卸し入力!$I:$I,0)),"") | E24: =IFERROR(INDEX(棚卸し入力!$C:$C,MATCH(23,棚卸し入力!$I:$I,0)),"") | F24: =IFERROR(INDEX(棚卸し入力!$A:$A,MATCH(23,棚卸し入力!$I:$I,0)),"")
A25: =IF(C25="","",24) | B25: =IFERROR(INDEX(棚卸し入力!$D:$D,MATCH(24,棚卸し入力!$I:$I,0)),"") | C25: =IFERROR(INDEX(棚卸し入力!$B:$B,MATCH(24,棚卸し入力!$I:$I,0)),"") | D25: =IFERROR(INDEX(棚卸し入力!$G:$G,MATCH(24,棚卸し入力!$I:$I,0)),"") | E25: =IFERROR(INDEX(棚卸し入力!$C:$C,MATCH(24,棚卸し入力!$I:$I,0)),"") | F25: =IFERROR(INDEX(棚卸し入力!$A:$A,MATCH(24,棚卸し入力!$I:$I,0)),"")
A26: =IF(C26="","",25) | B26: =IFERROR(INDEX(棚卸し入力!$D:$D,MATCH(25,棚卸し入力!$I:$I,0)),"") | C26: =IFERROR(INDEX(棚卸し入力!$B:$B,MATCH(25,棚卸し入力!$I:$I,0)),"") | D26: =IFERROR(INDEX(棚卸し入力!$G:$G,MATCH(25,棚卸し入力!$I:$I,0)),"") | E26: =IFERROR(INDEX(棚卸し入力!$C:$C,MATCH(25,棚卸し入力!$I:$I,0)),"") | F26: =IFERROR(INDEX(棚卸し入力!$A:$A,MATCH(25,棚卸し入力!$I:$I,0)),"")
A27: =IF(C27="","",26) | B27: =IFERROR(INDEX(棚卸し入力!$D:$D,MATCH(26,棚卸し入力!$I:$I,0)),"") | C27: =IFERROR(INDEX(棚卸し入力!$B:$B,MATCH(26,棚卸し入力!$I:$I,0)),"") | D27: =IFERROR(INDEX(棚卸し入力!$G:$G,MATCH(26,棚卸し入力!$I:$I,0)),"") | E27: =IFERROR(INDEX(棚卸し入力!$C:$C,MATCH(26,棚卸し入力!$I:$I,0)),"") | F27: =IFERROR(INDEX(棚卸し入力!$A:$A,MATCH(26,棚卸し入力!$I:$I,0)),"")
A28: =IF(C28="","",27) | B28: =IFERROR(INDEX(棚卸し入力!$D:$D,MATCH(27,棚卸し入力!$I:$I,0)),"") | C28: =IFERROR(INDEX(棚卸し入力!$B:$B,MATCH(27,棚卸し入力!$I:$I,0)),"") | D28: =IFERROR(INDEX(棚卸し入力!$G:$G,MATCH(27,棚卸し入力!$I:$I,0)),"") | E28: =IFERROR(INDEX(棚卸し入力!$C:$C,MATCH(27,棚卸し入力!$I:$I,0)),"") | F28: =IFERROR(INDEX(棚卸し入力!$A:$A,MATCH(27,棚卸し入力!$I:$I,0)),"")
A29: =IF(C29="","",28) | B29: =IFERROR(INDEX(棚卸し入力!$D:$D,MATCH(28,棚卸し入力!$I:$I,0)),"") | C29: =IFERROR(INDEX(棚卸し入力!$B:$B,MATCH(28,棚卸し入力!$I:$I,0)),"") | D29: =IFERROR(INDEX(棚卸し入力!$G:$G,MATCH(28,棚卸し入力!$I:$I,0)),"") | E29: =IFERROR(INDEX(棚卸し入力!$C:$C,MATCH(28,棚卸し入力!$I:$I,0)),"") | F29: =IFERROR(INDEX(棚卸し入力!$A:$A,MATCH(28,棚卸し入力!$I:$I,0)),"")
A30: =IF(C30="","",29) | B30: =IFERROR(INDEX(棚卸し入力!$D:$D,MATCH(29,棚卸し入力!$I:$I,0)),"") | C30: =IFERROR(INDEX(棚卸し入力!$B:$B,MATCH(29,棚卸し入力!$I:$I,0)),"") | D30: =IFERROR(INDEX(棚卸し入力!$G:$G,MATCH(29,棚卸し入力!$I:$I,0)),"") | E30: =IFERROR(INDEX(棚卸し入力!$C:$C,MATCH(29,棚卸し入力!$I:$I,0)),"") | F30: =IFERROR(INDEX(棚卸し入力!$A:$A,MATCH(29,棚卸し入力!$I:$I,0)),"")
A31: =IF(C31="","",30) | B31: =IFERROR(INDEX(棚卸し入力!$D:$D,MATCH(30,棚卸し入力!$I:$I,0)),"") | C31: =IFERROR(INDEX(棚卸し入力!$B:$B,MATCH(30,棚卸し入力!$I:$I,0)),"") | D31: =IFERROR(INDEX(棚卸し入力!$G:$G,MATCH(30,棚卸し入力!$I:$I,0)),"") | E31: =IFERROR(INDEX(棚卸し入力!$C:$C,MATCH(30,棚卸し入力!$I:$I,0)),"") | F31: =IFERROR(INDEX(棚卸し入力!$A:$A,MATCH(30,棚卸し入力!$I:$I,0)),"")
A32: =IF(C32="","",31) | B32: =IFERROR(INDEX(棚卸し入力!$D:$D,MATCH(31,棚卸し入力!$I:$I,0)),"") | C32: =IFERROR(INDEX(棚卸し入力!$B:$B,MATCH(31,棚卸し入力!$I:$I,0)),"") | D32: =IFERROR(INDEX(棚卸し入力!$G:$G,MATCH(31,棚卸し入力!$I:$I,0)),"") | E32: =IFERROR(INDEX(棚卸し入力!$C:$C,MATCH(31,棚卸し入力!$I:$I,0)),"") | F32: =IFERROR(INDEX(棚卸し入力!$A:$A,MATCH(31,棚卸し入力!$I:$I,0)),"")
A33: =IF(C33="","",32) | B33: =IFERROR(INDEX(棚卸し入力!$D:$D,MATCH(32,棚卸し入力!$I:$I,0)),"") | C33: =IFERROR(INDEX(棚卸し入力!$B:$B,MATCH(32,棚卸し入力!$I:$I,0)),"") | D33: =IFERROR(INDEX(棚卸し入力!$G:$G,MATCH(32,棚卸し入力!$I:$I,0)),"") | E33: =IFERROR(INDEX(棚卸し入力!$C:$C,MATCH(32,棚卸し入力!$I:$I,0)),"") | F33: =IFERROR(INDEX(棚卸し入力!$A:$A,MATCH(32,棚卸し入力!$I:$I,0)),"")
A34: =IF(C34="","",33) | B34: =IFERROR(INDEX(棚卸し入力!$D:$D,MATCH(33,棚卸し入力!$I:$I,0)),"") | C34: =IFERROR(INDEX(棚卸し入力!$B:$B,MATCH(33,棚卸し入力!$I:$I,0)),"") | D34: =IFERROR(INDEX(棚卸し入力!$G:$G,MATCH(33,棚卸し入力!$I:$I,0)),"") | E34: =IFERROR(INDEX(棚卸し入力!$C:$C,MATCH(33,棚卸し入力!$I:$I,0)),"") | F34: =IFERROR(INDEX(棚卸し入力!$A:$A,MATCH(33,棚卸し入力!$I:$I,0)),"")
A35: =IF(C35="","",34) | B35: =IFERROR(INDEX(棚卸し入力!$D:$D,MATCH(34,棚卸し入力!$I:$I,0)),"") | C35: =IFERROR(INDEX(棚卸し入力!$B:$B,MATCH(34,棚卸し入力!$I:$I,0)),"") | D35: =IFERROR(INDEX(棚卸し入力!$G:$G,MATCH(34,棚卸し入力!$I:$I,0)),"") | E35: =IFERROR(INDEX(棚卸し入力!$C:$C,MATCH(34,棚卸し入力!$I:$I,0)),"") | F35: =IFERROR(INDEX(棚卸し入力!$A:$A,MATCH(34,棚卸し入力!$I:$I,0)),"")
A36: =IF(C36="","",35) | B36: =IFERROR(INDEX(棚卸し入力!$D:$D,MATCH(35,棚卸し入力!$I:$I,0)),"") | C36: =IFERROR(INDEX(棚卸し入力!$B:$B,MATCH(35,棚卸し入力!$I:$I,0)),"") | D36: =IFERROR(INDEX(棚卸し入力!$G:$G,MATCH(35,棚卸し入力!$I:$I,0)),"") | E36: =IFERROR(INDEX(棚卸し入力!$C:$C,MATCH(35,棚卸し入力!$I:$I,0)),"") | F36: =IFERROR(INDEX(棚卸し入力!$A:$A,MATCH(35,棚卸し入力!$I:$I,0)),"")
A37: =IF(C37="","",36) | B37: =IFERROR(INDEX(棚卸し入力!$D:$D,MATCH(36,棚卸し入力!$I:$I,0)),"") | C37: =IFERROR(INDEX(棚卸し入力!$B:$B,MATCH(36,棚卸し入力!$I:$I,0)),"") | D37: =IFERROR(INDEX(棚卸し入力!$G:$G,MATCH(36,棚卸し入力!$I:$I,0)),"") | E37: =IFERROR(INDEX(棚卸し入力!$C:$C,MATCH(36,棚卸し入力!$I:$I,0)),"") | F37: =IFERROR(INDEX(棚卸し入力!$A:$A,MATCH(36,棚卸し入力!$I:$I,0)),"")
A38: =IF(C38="","",37) | B38: =IFERROR(INDEX(棚卸し入力!$D:$D,MATCH(37,棚卸し入力!$I:$I,0)),"") | C38: =IFERROR(INDEX(棚卸し入力!$B:$B,MATCH(37,棚卸し入力!$I:$I,0)),"") | D38: =IFERROR(INDEX(棚卸し入力!$G:$G,MATCH(37,棚卸し入力!$I:$I,0)),"") | E38: =IFERROR(INDEX(棚卸し入力!$C:$C,MATCH(37,棚卸し入力!$I:$I,0)),"") | F38: =IFERROR(INDEX(棚卸し入力!$A:$A,MATCH(37,棚卸し入力!$I:$I,0)),"")
A39: =IF(C39="","",38) | B39: =IFERROR(INDEX(棚卸し入力!$D:$D,MATCH(38,棚卸し入力!$I:$I,0)),"") | C39: =IFERROR(INDEX(棚卸し入力!$B:$B,MATCH(38,棚卸し入力!$I:$I,0)),"") | D39: =IFERROR(INDEX(棚卸し入力!$G:$G,MATCH(38,棚卸し入力!$I:$I,0)),"") | E39: =IFERROR(INDEX(棚卸し入力!$C:$C,MATCH(38,棚卸し入力!$I:$I,0)),"") | F39: =IFERROR(INDEX(棚卸し入力!$A:$A,MATCH(38,棚卸し入力!$I:$I,0)),"")
A40: =IF(C40="","",39) | B40: =IFERROR(INDEX(棚卸し入力!$D:$D,MATCH(39,棚卸し入力!$I:$I,0)),"") | C40: =IFERROR(INDEX(棚卸し入力!$B:$B,MATCH(39,棚卸し入力!$I:$I,0)),"") | D40: =IFERROR(INDEX(棚卸し入力!$G:$G,MATCH(39,棚卸し入力!$I:$I,0)),"") | E40: =IFERROR(INDEX(棚卸し入力!$C:$C,MATCH(39,棚卸し入力!$I:$I,0)),"") | F40: =IFERROR(INDEX(棚卸し入力!$A:$A,MATCH(39,棚卸し入力!$I:$I,0)),"")
...
